<?xml version="1.0" ?>
<robot name="obslidar" xmlns:xacro="http://www.ros.org/wiki/xacro">

<xacro:include filename="$(find obslidar_description)/urdf/materials.xacro" />
<xacro:include filename="$(find obslidar_description)/urdf/obslidar.ros2control" />
<xacro:include filename="$(find obslidar_description)/urdf/obslidar.gazebo" />
<link name="base_link">
  <inertial>
    <origin xyz="0.002772581033872373 -5.4066491640116266e-05 0.030212240137112302" rpy="0 0 0"/>
    <mass value="0.8477349431623675"/>
    <inertia ixx="0.00114" iyy="0.001352" izz="0.002259" ixy="-2e-06" iyz="-0.0" ixz="-9e-06"/>
  </inertial>
  <visual>
    <origin xyz="0 0 0" rpy="0 0 0"/>
    <geometry>
      <mesh filename="file://$(find obslidar_description)/meshes/base_link.stl" scale="0.001 0.001 0.001"/>
    </geometry>
    <material name="silver"/>
  </visual>
  <collision>
    <origin xyz="0 0 0" rpy="0 0 0"/>
    <geometry>
      <mesh filename="file://$(find obslidar_description)/meshes/base_link.stl" scale="0.001 0.001 0.001"/>
    </geometry>
  </collision>
</link>

<link name="left_wheel_1">
  <inertial>
    <origin xyz="-7.450554201371418e-10 0.007500460673573815 3.725290319278596e-10" rpy="0 0 0"/>
    <mass value="0.027116853339001133"/>
    <inertia ixx="5e-06" iyy="9e-06" izz="5e-06" ixy="-0.0" iyz="0.0" ixz="0.0"/>
  </inertial>
  <visual>
    <origin xyz="0.05 -0.059468 -0.025" rpy="0 0 0"/>
    <geometry>
      <mesh filename="file://$(find obslidar_description)/meshes/left_wheel_1.stl" scale="0.001 0.001 0.001"/>
    </geometry>
    <material name="silver"/>
  </visual>
  <collision>
    <origin xyz="0.05 -0.059468 -0.025" rpy="0 0 0"/>
    <geometry>
      <mesh filename="file://$(find obslidar_description)/meshes/left_wheel_1.stl" scale="0.001 0.001 0.001"/>
    </geometry>
  </collision>
</link>

<link name="castro_wheel_1">
  <inertial>
    <origin xyz="0.05 -2.120369787642344e-18 -0.00375" rpy="0 0 0"/>
    <mass value="0.016441001553786586"/>
    <inertia ixx="0.0" iyy="0.0" izz="1e-06" ixy="-0.0" iyz="-0.0" ixz="0.0"/>
  </inertial>
  <visual>
    <origin xyz="-0.0 -0.0 -0.01" rpy="0 0 0"/>
    <geometry>
      <mesh filename="file://$(find obslidar_description)/meshes/castro_wheel_1.stl" scale="0.001 0.001 0.001"/>
    </geometry>
    <material name="silver"/>
  </visual>
  <collision>
    <origin xyz="-0.0 -0.0 -0.01" rpy="0 0 0"/>
    <geometry>
      <mesh filename="file://$(find obslidar_description)/meshes/castro_wheel_1.stl" scale="0.001 0.001 0.001"/>
    </geometry>
  </collision>
</link>

<link name="lidar_1">
  <inertial>
    <origin xyz="0.0 -2.8271597168564596e-18 0.009999999999999988" rpy="0 0 0"/>
    <mass value="0.032421236185046665"/>
    <inertia ixx="4e-06" iyy="4e-06" izz="6e-06" ixy="0.0" iyz="-0.0" ixz="-0.0"/>
  </inertial>
  <visual>
    <origin xyz="-0.05 -0.0 -0.055" rpy="0 0 0"/>
    <geometry>
      <mesh filename="file://$(find obslidar_description)/meshes/lidar_1.stl" scale="0.001 0.001 0.001"/>
    </geometry>
    <material name="silver"/>
  </visual>
  <collision>
    <origin xyz="-0.05 -0.0 -0.055" rpy="0 0 0"/>
    <geometry>
      <mesh filename="file://$(find obslidar_description)/meshes/lidar_1.stl" scale="0.001 0.001 0.001"/>
    </geometry>
  </collision>
</link>

<link name="right_wheel_1">
  <inertial>
    <origin xyz="-7.450554548316113e-10 -0.007499539326426177 3.7252857049141497e-10" rpy="0 0 0"/>
    <mass value="0.027116853339001133"/>
    <inertia ixx="5e-06" iyy="9e-06" izz="5e-06" ixy="-0.0" iyz="0.0" ixz="-0.0"/>
  </inertial>
  <visual>
    <origin xyz="0.05 0.060532 -0.025" rpy="0 0 0"/>
    <geometry>
      <mesh filename="file://$(find obslidar_description)/meshes/right_wheel_1.stl" scale="0.001 0.001 0.001"/>
    </geometry>
    <material name="silver"/>
  </visual>
  <collision>
    <origin xyz="0.05 0.060532 -0.025" rpy="0 0 0"/>
    <geometry>
      <mesh filename="file://$(find obslidar_description)/meshes/right_wheel_1.stl" scale="0.001 0.001 0.001"/>
    </geometry>
  </collision>
</link>

<joint name="left_joint" type="continuous">
  <origin xyz="-0.05 0.059468 0.025" rpy="0 0 0"/>
  <parent link="base_link"/>
  <child link="left_wheel_1"/>
  <axis xyz="0.0 1.0 0.0"/>
</joint>

<joint name="castro_joint" type="fixed">
  <origin xyz="0.0 0.0 0.01" rpy="0 0 0"/>
  <parent link="base_link"/>
  <child link="castro_wheel_1"/>
</joint>

<joint name="lidar_joint" type="fixed">
  <origin xyz="0.05 0.0 0.055" rpy="0 0 0"/>
  <parent link="base_link"/>
  <child link="lidar_1"/>
</joint>

<joint name="right_joint" type="continuous">
  <origin xyz="-0.05 -0.060532 0.025" rpy="0 0 0"/>
  <parent link="base_link"/>
  <child link="right_wheel_1"/>
  <axis xyz="0.0 -1.0 0.0"/>
</joint>

</robot>
